Workbook

Sheet Sample Selection Criteria
A1: Sample Selection Rule — Corporate Governance, Financing Choices, and Visible Investment Signals in Indian FinTech Firms
A3: Sampling approach: Purposive (judgmental) sampling of Indian listed firms, appropriate for exploratory/panel-based governance-finance research on a still-emerging FinTech population in India.
A5: Inclusion criteria:
A6: 1. Listed on NSE and/or BSE — ensures mandatory SEBI LODR disclosures (audited financials, Corporate Governance Report, Board composition) are publicly available.
A7: 2. Primary business model falls under one of the following FinTech-linked categories:
A8: (a) FinTech / Digital Payments (payments platforms, prepaid instruments, digital wallets)
A9: (b) Online Insurance / Financial Intermediation (InsurTech, digital distribution)
A10: (c) FinTech Infrastructure (Registrar & Transfer Agents, Depositories, Exchanges, market infrastructure institutions)
A11: (d) FinTech / Core Banking & BFSI Software (technology providers to banks, NBFCs, capital markets)
A12: (e) Digital Broking / Wealth-Tech (technology-led stockbroking, wealth management platforms)
A13: (f) Technology-enabled NBFC / Digital Lending (NBFCs and microfinance institutions whose origination, underwriting or distribution is predominantly digital/tech-enabled)
A14: 3. At least 3 consecutive financial years of standalone/consolidated financial statements and Corporate Governance Reports publicly available (via company Annual Reports, BSE/NSE corporate filings, or aggregators such as Screener.in, Moneycontrol, ACE Equity).
... A27: Note on data collection: Some firms reported zero debt, which was retained as reported rather than treated as missing data. Negative shareholders’ equity and other unusual financial observations were also retained because they represent the actual financial position of the respective firms and may be relevant to the analysis. For companies that were listed after the beginning of the study period, only observations available and comparable under the study’s criteria were considered. Similarly, differences in company age, listing year, business scale, and financial structure were not used as reasons for removing observations unless they conflicted with the predefined sample-selection criteria.

Sheet Raw Data
A1: Firm | B1: Ticker (NSE/BSE) | C1: Category | D1: Listing Year | E1: Year | F1: Assets | G1: Debt | H1: Equity | I1: CAPEX | J1: Revenue | K1: Net Income | L1: Cash | M1: Board Size | N1: Independent Directors | O1: % Independent Directors | P1: Data Source | Q1: Notes | R1: FirmYear Key (helper)
A2: One97 Communications Ltd (Paytm) | B2: NSE: PAYTM | C2: FinTech - Digital Payments | D2: 2021 | E2: FY2021 | F2: 9151.3 | G2: 544.9 | H2: 6516.2 | I2: 192.7 | J2: 2802.4 | K2: -1701 | L2: 546.8 | O2: 0 | P2: Data extracted from your 4 annual reports | Q2: . *FY2021 board composition isn't disclosed — Paytm was unlisted until Nov 2021. FY figures were originally in ₹ Million I've converted to ₹ Crore for consistency | R2: =A2&"_"&MID(E2,3,4) -> One97 Communications Ltd (Paytm)_2021
A3: One97 Communications Ltd (Paytm) | B3: NSE: PAYTM | C3: FinTech - Digital Payments | D3: 2021 | E3: FY2022 | F3: 17991.6 | G3: 0.1 | H3: 14129.5 | I3: 507.1 | J3: 4974.2 | K3: -2396.4 | L3: 1379 | M3: 8 | N3: 4 | O3: =IFERROR(N3/M3,"") -> 0.5 | P3: Data extracted from your 4 annual reports | R3: =A3&"_"&MID(E3,3,4) -> One97 Communications Ltd (Paytm)_2022
A4: One97 Communications Ltd (Paytm) | B4: NSE: PAYTM | C4: FinTech - Digital Payments | D4: 2021 | E4: FY2023 | F4: 17965.8 | G4: 2 | H4: 12992.9 | I4: 705.2 | J4: 7990.3 | K4: -1776.5 | L4: 3312 | M4: 7 | N4: 4 | O4: =IFERROR(N4/M4,"") -> 0.57142857 | P4: Data extracted from your 4 annual reports | Q4: CAPEX = Purchase of property, plant & equipment (including intangibles) from the Cash Flow Statement. | R4: =A4&"_"&MID(E4,3,4) -> One97 Communications Ltd (Paytm)_2023
A5: One97 Communications Ltd (Paytm) | B5: NSE: PAYTM | C5: FinTech - Digital Payments | D5: 2021 | E5: FY2024 | F5: 17139.1 | G5: Nil | H5: 13298.4 | I5: 821.7 | J5: 9977.8 | K5: -1422.4 | L5: 4277.2 | M5: 7 | N5: 4 | O5: =IFERROR(N5/M5,"") -> 0.57142857 | P5: Data extracted from your 4 annual reports | Q5: Debt = total Borrowings line in the Balance Sheet — Paytm carries almost no formal debt (it funds itself off IPO cash reserves), just small working-capital overdrafts in a few years. | R5: =A5&"_"&MID(E5,3,4) -> One97 Communications Ltd (Paytm)_2024
A6: PB Fintech Ltd (Policybazaar) | B6: NSE: POLICYBZR | C6: FinTech - Online Insurance Intermediation | D6: 2021 | E6: FY2021 | F6: 2330.73 | G6: Nil | H6: 1991.73 | I6: 5.82 | J6: 886.66 | K6: -150.24 | L6: 438.77 | O6: =IFERROR(N6/M6,"") | P6: Data extracted from your 4 annual reports | R6: =A6&"_"&MID(E6,3,4) -> PB Fintech Ltd (Policybazaar)_2021
A7: PB Fintech Ltd (Policybazaar) | B7: NSE: POLICYBZR | C7: FinTech - Online Insurance Intermediation | D7: 2021 | E7: FY2022 | F7: 5915.48 | G7: Nil | H7: 5411.66 | I7: 32.74 | J7: 1424.89 | K7: -832.91 | L7: 367.4 | M7: 9 | N7: 5 | O7: =IFERROR(N7/M7,"") -> 0.55555556 | P7: Data extracted from your 4 annual reports | Q7: FY2021 Board Size/Independent Directors should be entered as N/A, because the FY2021-22 report does not provide a March 31, 2021 board-composition figure. I would not put 0 there. | R7: =A7&"_"&MID(E7,3,4) -> PB Fintech Ltd (Policybazaar)_2022
A8: PB Fintech Ltd (Policybazaar) | B8: NSE: POLICYBZR | C8: FinTech - Online Insurance Intermediation | D8: 2021 | E8: FY2023 | F8: 6254.02 | G8: Nil | H8: 5484.8 | I8: 65.7 | J8: 2557.85 | K8: -487.94 | L8: 72.34 | M8: 9 | N8: 5 | O8: =IFERROR(N8/M8,"") -> 0.55555556 | P8: Data extracted from your 4 annual reports | Q8: CAPEX is calculated as the purchase of property, plant & equipment plus intangible assets, matching the approach used in the sheet's Paytm note. | R8: =A8&"_"&MID(E8,3,4) -> PB Fintech Ltd (Policybazaar)_2023
A9: PB Fintech Ltd (Policybazaar) | B9: NSE: POLICYBZR | C9: FinTech - Online Insurance Intermediation | D9: 2021 | E9: FY2024 | F9: 6728.51 | G9: Nil | H9: 5876.47 | I9: 63.35 | J9: 3437.68 | K9: 64.41 | L9: 324.86 | M9: 9 | N9: 5 | O9: =IFERROR(N9/M9,"") -> 0.55555556 | P9: Data extracted from your 4 annual reports | Q9: The FY2022 and FY2023 consolidated figures are reported in ₹ lakhs in the annual report; converted in crore. | R9: =A9&"_"&MID(E9,3,4) -> PB Fintech Ltd (Policybazaar)_2024
A10: Computer Age Management Services Ltd (CAMS) | B10: NSE: CAMS | C10: FinTech Infrastructure (RTA/Depository/Exchange) | D10: 2020 | E10: FY2021 | F10: 841.93 | G10: 0 | H10: 515.87 | I10: 26.68 | J10: 705.5 | K10: 205.29 | L10: 17.43 | M10: 7 | N10: 3 | O10: =IFERROR(N10/M10,"") -> 0.42857143 | P10: Data extracted from your 4 annual reports | R10: =A10&"_"&MID(E10,3,4) -> Computer Age Management Services Ltd (CAMS)_2021
A11: Computer Age Management Services Ltd (CAMS) | B11: NSE: CAMS | C11: FinTech Infrastructure (RTA/Depository/Exchange) | D11: 2020 | E11: FY2022 | F11: 957.07 | G11: 0 | H11: 647.64 | I11: 62.25 | J11: 909.67 | K11: 286.95 | L11: 4.51 | M11: 7 | N11: 3 | O11: =IFERROR(N11/M11,"") -> 0.42857143 | P11: Data extracted from your 4 annual reports | Q11: Debt = ₹0.00 crore because CAMS' consolidated balance sheets do not report borrowings; lease liabilities are shown separately. For consistency, I have not treated lease liabilities as debt. | R11: =A11&"_"&MID(E11,3,4) -> Computer Age Management Services Ltd (CAMS)_2022
A12: Computer Age Management Services Ltd (CAMS) | B12: NSE: CAMS | C12: FinTech Infrastructure (RTA/Depository/Exchange) | D12: 2020 | E12: FY2023 | F12: 1097.55 | G12: 0 | H12: 782.47 | I12: 44.51 | J12: 971.83 | K12: 284.63 | L12: 16.39 | M12: 7 | N12: 3 | O12: =IFERROR(N12/M12,"") -> 0.42857143 | P12: Data extracted from your 4 annual reports | Q12: CAPEX = capital expenditure on PPE + intangible assets, matching the annual report's cash-flow presentation. For FY2024, this is ₹3,837.11 lakh = ₹38.37 crore. | R12: =A12&"_"&MID(E12,3,4) -> Computer Age Management Services Ltd (CAMS)_2023
A13: Computer Age Management Services Ltd (CAMS) | B13: NSE: CAMS | C13: FinTech Infrastructure (RTA/Depository/Exchange) | D13: 2020 | E13: FY2024 | F13: 1097.55 | G13: 0 | H13: 915.65 | I13: 38.37 | J13: 1136.52 | K13: 350.98 | L13: 6.74 | M13: 6 | N13: 3 | O13: =IFERROR(N13/M13,"") -> 0.5 | P13: Data extracted from your 4 annual reports | Q13: FY2024 revenue = ₹1,136.52 crore and profit = ₹350.98 crore; the annual report gives ₹1,13,652 lakh revenue and ₹35,097.73 lakh profit | R13: =A13&"_"&MID(E13,3,4) -> Computer Age Management Services Ltd (CAMS)_2024
A14: Central Depository Services (India) Ltd (CDSL) | B14: NSE: CDSL | C14: FinTech Infrastructure (RTA/Depository/Exchange) | D14: 2017 | E14: FY2021 | F14: 1084 | G14: 0 | H14: 920 | I14: 8.34 | J14: 343.72 | K14: 201.27 | L14: 41.89 | M14: 8 | N14: 5 | O14: =IFERROR(N14/M14,"") -> 0.625 | P14: Data extracted from your 4 annual reports | R14: =A14&"_"&MID(E14,3,4) -> Central Depository Services (India) Ltd (CDSL)_2021
A15: Central Depository Services (India) Ltd (CDSL) | B15: NSE: CDSL | C15: FinTech Infrastructure (RTA/Depository/Exchange) | D15: 2017 | E15: FY2022 | F15: 1325.56 | G15: 0 | H15: 1136.3 | I15: 44.54 | J15: 551.33 | K15: 311.81 | L15: 85.59 | M15: 8 | N15: 5 | O15: =IFERROR(N15/M15,"") -> 0.625 | P15: Data extracted from your 4 annual reports | Q15: The FY2024 consolidated P&L reports revenue of ₹812.26 crore and net profit of ₹419.55 crore. | R15: =A15&"_"&MID(E15,3,4) -> Central Depository Services (India) Ltd (CDSL)_2022
A16: Central Depository Services (India) Ltd (CDSL) | B16: NSE: CDSL | C16: FinTech Infrastructure (RTA/Depository/Exchange) | D16: 2017 | E16: FY2023 | F16: 1457.17 | G16: 0 | H16: 1257.14 | I16: 205.59 | J16: 555.09 | K16: 275.96 | L16: 50.36 | M16: 9 | N16: 6 | O16: =IFERROR(N16/M16,"") -> 0.66666667 | P16: Data extracted from your 4 annual reports | Q16: Debt = 0.00 because the annual report explicitly states there was no borrowing. | R16: =A16&"_"&MID(E16,3,4) -> Central Depository Services (India) Ltd (CDSL)_2023
A17: Central Depository Services (India) Ltd (CDSL) | B17: NSE: CDSL | C17: FinTech Infrastructure (RTA/Depository/Exchange) | D17: 2017 | E17: FY2024 | F17: 1781.65 | G17: 0 | H17: 1507.19 | I17: 73.46 | J17: 812.26 | K17: 419.55 | L17: 18.48 | M17: 9 | N17: 6 | O17: =IFERROR(N17/M17,"") -> 0.66666667 | P17: Data extracted from your 4 annual reports | Q17: FY2024 CAPEX is ₹73.46 crore based on PPE and intangible assets acquired. | R17: =A17&"_"&MID(E17,3,4) -> Central Depository Services (India) Ltd (CDSL)_2024
A18: BSE Ltd | B18: NSE: BSE | C18: FinTech Infrastructure (RTA/Depository/Exchange) | D18: 2017 | E18: FY2021 | F18: 4627.08 | G18: 0 | H18: 2515.93 | I18: 38.19 | J18: 501.37 | K18: 141.7 | L18: 416.15 | M18: 8 | N18: 6 | O18: =IFERROR(N18/M18,"") -> 0.75 | P18: Data extracted from your 4 annual reports | Q18: BSE Annual Report 2020-21. Consolidated assets were ₹4,62,708 lakh, total equity ₹2,51,593 lakh and cash ₹41,615 lakh. | R18: =A18&"_"&MID(E18,3,4) -> BSE Ltd_2021
A19: BSE Ltd | B19: NSE: BSE | C19: FinTech Infrastructure (RTA/Depository/Exchange) | D19: 2017 | E19: FY2022 | F19: 6185.4 | G19: 0 | H19: 2789.71 | I19: 31.96 | J19: 743.15 | K19: 244.93 | L19: 886.94 | M19: 8 | N19: 6 | O19: =IFERROR(N19/M19,"") -> 0.75 | P19: Data extracted from your 4 annual reports | Q19: Board strength was 8, comprising 6 Public Interest Directors | R19: =A19&"_"&MID(E19,3,4) -> BSE Ltd_2022
A20: BSE Ltd | B20: NSE: BSE | C20: FinTech Infrastructure (RTA/Depository/Exchange) | D20: 2017 | E20: FY2023 | F20: 5993.81 | G20: 0 | H20: 2828.99 | I20: 143.42 | J20: 815.53 | K20: 166.91 | L20: 452.99 | M20: 9 | N20: 7 | O20: =IFERROR(N20/M20,"") -> 0.77777778 | P20: Data extracted from your 4 annual reports | Q20: I have treated Debt as borrowings, not lease liabilities or other financial liabilities | R20: =A20&"_"&MID(E20,3,4) -> BSE Ltd_2023
A21: BSE Ltd | B21: NSE: BSE | C21: FinTech Infrastructure (RTA/Depository/Exchange) | D21: 2017 | E21: FY2024 | F21: 9450.23 | G21: 0 | H21: 3454.66 | I21: 131.32 | J21: 1390.03 | K21: 753.39 | L21: 2112.49 | M21: 9 | N21: 7 | O21: =IFERROR(N21/M21,"") -> 0.77777778 | P21: Data extracted from your 4 annual reports | Q21: BSE Annual Report 2023-24. Total assets ₹9,45,023 lakh, total equity ₹3,45,466 lakh. | R21: =A21&"_"&MID(E21,3,4) -> BSE Ltd_2024
A22: Angel One Ltd | B22: NSE: ANGELONE | C22: Digital Broking / Wealth-Tech | D22: 2018 | E22: FY2021 | F22: 4813.83 | G22: 1171.47 | H22: 1130.997 | I22: 14.42 | J22: 1263.68 | K22: 296.86 | L22: 82.04 | M22: 6 | N22: 3 | O22: =IFERROR(N22/M22,"") -> 0.5 | P22: Data extracted from your 4 annual reports | Q22: Debt: Borrowings + Debt Securities, consistent with Angel One's own definition of debt. The FY2024 report explicitly defines debt as borrowings plus debt securities. | R22: =A22&"_"&MID(E22,3,4) -> Angel One Ltd_2021
A23: Angel One Ltd | B23: NSE: ANGELONE | C23: Digital Broking / Wealth-Tech | D23: 2018 | E23: FY2022 | F23: 7219.94 | G23: 1257.73 | H23: 1584.38 | I23: 69.75 | J23: 2258.61 | K23: 624.81 | L23: 422.11 | M23: 7 | N23: 4 | O23: =IFERROR(N23/M23,"") -> 0.57142857 | P23: Data extracted from your 4 annual reports | Q23: Cash and Cash Equivalents only, not bank balances. | R23: =A23&"_"&MID(E23,3,4) -> Angel One Ltd_2022
A24: Angel One Ltd | B24: NSE: ANGELONE | C24: Digital Broking / Wealth-Tech | D24: 2018 | E24: FY2023 | F24: 7477.67 | G24: 787.95 | H24: 2161.56 | I24: 114.16 | J24: 3001.59 | K24: 889.95 | L24: 133.06 | M24: 9 | N24: 6 | O24: =IFERROR(N24/M24,"") -> 0.66666667 | P24: Data extracted from your 4 annual reports | Q24: Purchase of property, plant & equipment and intangible assets from the consolidated cash-flow statement. | R24: =A24&"_"&MID(E24,3,4) -> Angel One Ltd_2023
A25: Angel One Ltd | B25: NSE: ANGELONE | C25: Digital Broking / Wealth-Tech | D25: 2018 | E25: FY2024 | F25: 13253.73 | G25: 2535.34 | H25: 3038.6 | I25: 207.51 | J25: 4271.68 | K25: 1125.53 | L25: 1042.99 | M25: 9 | N25: 5 | O25: =IFERROR(N25/M25,"") -> 0.55555556 | P25: Data extracted from your 4 annual reports | Q25: FY2024 retained a 9-member Board, but independent directors reduced to 5. Kamalji Sahay and Uday Sankar Roy completed their five-year terms in May 2023, while Amit Majumdar joined as a Whole-Time Director in April 2023. | R25: =A25&"_"&MID(E25,3,4) -> Angel One Ltd_2024
A26: 5paisa Capital Ltd | B26: NSE: 5PAISA | C26: Digital Broking / Wealth-Tech | D26: 2019 | E26: FY2021 | F26: 866.89 | G26: 233.93 | H26: 156.08 | I26: 4.13 | J26: 192.91 | K26: 14.69 | L26: 16.88 | M26: 7 | N26: 4 | O26: =IFERROR(N26/M26,"") -> 0.57142857 | P26: Data extracted from your 4 annual reports | R26: =A26&"_"&MID(E26,3,4) -> 5paisa Capital Ltd_2021
A27: 5paisa Capital Ltd | B27: NSE: 5PAISA | C27: Digital Broking / Wealth-Tech | D27: 2019 | E27: FY2022 | F27: 1608.56 | G27: 278.98 | H27: 373.98 | I27: 7.46 | J27: 296.97 | K27: 13.74 | L27: 89.41 | M27: 7 | N27: 4 | O27: =IFERROR(N27/M27,"") -> 0.57142857 | P27: Data extracted from your 4 annual reports | R27: =A27&"_"&MID(E27,3,4) -> 5paisa Capital Ltd_2022
A28: 5paisa Capital Ltd | B28: NSE: 5PAISA | C28: Digital Broking / Wealth-Tech | D28: 2019 | E28: FY2023 | F28: 1641.63 | G28: 169.28 | H28: 463.26 | I28: 13.57 | J28: 337.87 | K28: 43.57 | L28: 20.93 | M28: 6 | N28: 4 | O28: =IFERROR(N28/M28,"") -> 0.66666667 | P28: Data extracted from your 4 annual reports | R28: =A28&"_"&MID(E28,3,4) -> 5paisa Capital Ltd_2023
A29: 5paisa Capital Ltd | B29: NSE: 5PAISA | C29: Digital Broking / Wealth-Tech | D29: 2019 | E29: FY2024 | F29: 2047.85 | G29: 336.32 | H29: 539.89 | I29: 19.42 | J29: 394.57 | K29: 54.44 | L29: 70.91 | M29: 6 | N29: 4 | O29: =IFERROR(N29/M29,"") -> 0.66666667 | P29: Data extracted from your 4 annual reports | R29: =A29&"_"&MID(E29,3,4) -> 5paisa Capital Ltd_2024
A30: Infibeam Avenues Ltd | B30: NSE: INFIBEAM | C30: FinTech - Digital Payments | D30: 2016 | E30: FY2021 | F30: 3549.64 | G30: 19.83 | H30: 2887.91 | I30: 84.2 | J30: 676.04 | K30: 70.25 | L30: 177.41 | M30: 7 | N30: 4 | O30: =IFERROR(N30/M30,"") -> 0.57142857 | P30: Data extracted from your 4 annual reports | Q30: Infibeam crossed ₹1 lakh crore of payment processing during FY21 and entered into strategic enterprise-platform/payment arrangements with Jio Platforms and JPMC Bank India. | R30: =A30&"_"&MID(E30,3,4) -> Infibeam Avenues Ltd_2021
A31: Infibeam Avenues Ltd | B31: NSE: INFIBEAM | C31: FinTech - Digital Payments | D31: 2016 | E31: FY2022 | F31: 3854.34 | G31: 0.21 | H31: 2954.85 | I31: 82.19 | J31: 1293.93 | K31: 83.65 | L31: 208.8 | M31: 7 | N31: 4 | O31: =IFERROR(N31/M31,"") -> 0.57142857 | P31: Data extracted from your 4 annual reports | Q31: Infibeam launched CCAvenue TapPay, its smartphone-based SoftPOS solution, in July 2022 | R31: =A31&"_"&MID(E31,3,4) -> Infibeam Avenues Ltd_2022
A32: Infibeam Avenues Ltd | B32: NSE: INFIBEAM | C32: FinTech - Digital Payments | D32: 2016 | E32: FY2023 | F32: 4104.02 | G32: 0 | H32: 3166.46 | I32: 34.29 | J32: 1962.34 | K32: 136.27 | L32: 270.02 | M32: 7 | N32: 4 | O32: =IFERROR(N32/M32,"") -> 0.57142857 | P32: Data extracted from your 4 annual reports | Q32: Received in-principle RBI approval for a Payment Aggregator licence and a perpetual BBPOU licence. It also became the first payment gateway player in India to process CBDC transactions for online retail merchants. | R32: =A32&"_"&MID(E32,3,4) -> Infibeam Avenues Ltd_2023
A33: Infibeam Avenues Ltd | B33: NSE: INFIBEAM | C33: FinTech - Digital Payments | D33: 2016 | E33: FY2024 | F33: 5216.07 | G33: 71.72 | H33: 3455.74 | I33: 291.85 | J33: 3171.09 | K33: 155.95 | L33: 707.32 | M33: 7 | N33: 4 | O33: =IFERROR(N33/M33,"") -> 0.57142857 | P33: Data extracted from your 4 annual reports | Q33: : Infibeam received final RBI authorisation for its Payment Aggregator and perpetual BBPS licences, launched THEIA, its video-AI platform, and made strategic investments in Pirimid Technologies and So Hum Bharat Digital Payments. | R33: =A33&"_"&MID(E33,3,4) -> Infibeam Avenues Ltd_2024
A34: Zaggle Prepaid Ocean Services Ltd | B34: NSE: ZAGGLE | C34: FinTech - Digital Payments | D34: 2023 | E34: FY2021 | F34: 59.57 | G34: 33.65 | H34: -44.73 | I34: 1.62 | J34: 222.31 | K34: 24.47 | L34: 3.31 | M34: 2 | N34: 0 | O34: =IFERROR(N34/M34,"") -> 0 | P34: Data extracted from your 4 annual reports | Q34: Outstanding unsecured loans were approximately ₹5.65 crore, including loans from banks/financial institutions and a director. | R34: =A34&"_"&MID(E34,3,4) -> Zaggle Prepaid Ocean Services Ltd_2021
A35: Zaggle Prepaid Ocean Services Ltd | B35: NSE: ZAGGLE | C35: FinTech - Digital Payments | D35: 2023 | E35: FY2022 | F35: 92.65 | G35: 64.47 | H35: -3.56 | I35: 1.62 | J35: 371.26 | K35: 41.92 | L35: 0.71 | M35: 2 | N35: 0 | O35: =IFERROR(N35/M35,"") -> 0 | P35: Data extracted from your 4 annual reports | Q35: PAT increased to ₹41.92 crore from ₹19.33 crore. | R35: =A35&"_"&MID(E35,3,4) -> Zaggle Prepaid Ocean Services Ltd_2022
A36: Zaggle Prepaid Ocean Services Ltd | B36: NSE: ZAGGLE | C36: FinTech - Digital Payments | D36: 2023 | E36: FY2023 | F36: 234.76 | G36: 121.07 | H36: 48.75 | I36: 4.59 | J36: 553.46 | K36: 22.9 | L36: 19.59 | M36: 2 | N36: 0 | O36: =IFERROR(N36/M36,"") -> 0 | P36: Data extracted from your 4 annual reports | Q36: The company launched Zoyer and expanded its customer/user base | R36: =A36&"_"&MID(E36,3,4) -> Zaggle Prepaid Ocean Services Ltd_2023
A37: Zaggle Prepaid Ocean Services Ltd | B37: NSE: ZAGGLE | C37: FinTech - Digital Payments | D37: 2023 | E37: FY2024 | F37: 696.14 | G37: 73.6 | H37: 575.38 | I37: 4.59 | J37: 775.6 | K37: 44.02 | L37: 7.94 | M37: 7 | N37: 4 | O37: =IFERROR(N37/M37,"") -> 0.57142857 | P37: Data extracted from your 4 annual reports | Q37: Zaggle's IPO resulted in its shares being listed on BSE and NSE on September 22, 2023. | R37: =A37&"_"&MID(E37,3,4) -> Zaggle Prepaid Ocean Services Ltd_2024
A38: Fino Payments Bank Ltd | B38: NSE: FINOPB | C38: FinTech - Digital Payments | D38: 2021 | E38: FY2021 | F38: 1010.3 | G38: 180.8 | H38: 150.6 | I38: 69 | J38: 791 | K38: 20.5 | L38: 270.8 | O38: =IFERROR(N38/M38,"") | P38: Data extracted from your 4 annual reports | R38: =A38&"_"&MID(E38,3,4) -> Fino Payments Bank Ltd_2021
A39: Fino Payments Bank Ltd | B39: NSE: FINOPB | C39: FinTech - Digital Payments | D39: 2021 | E39: FY2022 | F39: 1680 | G39: 249.7 | H39: 479.8 | I39: 64.4 | J39: 1008.9 | K39: 42.7 | L39: 766.2 | M39: 8 | N39: 5 | O39: =IFERROR(N39/M39,"") -> 0.625 | P39: Data extracted from your 4 annual reports | Q39: Revenue = Total Income (Interest earned + Other income), since a bank-format P&L has no separate "Revenue from operations" line — for this payments bank, nearly all revenue is fee-based and sits in "Other income." | R39: =A39&"_"&MID(E39,3,4) -> Fino Payments Bank Ltd_2022
A40: Fino Payments Bank Ltd | B40: NSE: FINOPB | C40: FinTech - Digital Payments | D40: 2021 | E40: FY2023 | F40: 2466.4 | G40: 434.1 | H40: 552.5 | I40: 94.3 | J40: 1229.9 | K40: 65.1 | L40: 833.9 | M40: 7 | N40: 5 | O40: =IFERROR(N40/M40,"") -> 0.71428571 | P40: Data extracted from your 4 annual reports | Q40: Debt = "Borrowings" line from the Balance Sheet — unlike Paytm/PB Fintech, Fino Payments Bank does carry real borrowings (working capital/refinance lines), not just lease liabilities. | R40: =A40&"_"&MID(E40,3,4) -> Fino Payments Bank Ltd_2023
...

Sheet Calculated Variables
A1: Calculated Variables — Research Panel Dataset (Indian FinTech Firms)
A2: Derived from 'Raw Data' sheet. All cells are live formulas; edit the source data and this sheet recalculates.
A4: FirmYear | B4: Investment | C4: Leverage | D4: ROA | E4: Firm Size | F4: Board Independence
A5: ='Raw Data'!R2 -> One97 Communications Ltd (Paytm)_2021 | B5: =IFERROR(ROUND(SUMIF('Raw Data'!$R:$R,$A5,'Raw Data'!$I:$I)/SUMIF('Raw Data'!$R:$R,$A5,'Raw Data'!$F:$F),4),"NA") -> 0.0211 | C5: =IFERROR(ROUND(SUMIF('Raw Data'!$R:$R,$A5,'Raw Data'!$G:$G)/SUMIF('Raw Data'!$R:$R,$A5,'Raw Data'!$F:$F),4),"NA") -> 0.0595 | D5: =IFERROR(ROUND(SUMIF('Raw Data'!$R:$R,$A5,'Raw Data'!$K:$K)/SUMIF('Raw Data'!$R:$R,$A5,'Raw Data'!$F:$F),4),"NA") -> -0.1859 | E5: =IFERROR(ROUND(LN(SUMIF('Raw Data'!$R:$R,$A5,'Raw Data'!$F:$F)),4),"NA") -> 9.1217 | F5: =IFERROR(ROUND(SUMIF('Raw Data'!$R:$R,$A5,'Raw Data'!$N:$N)/SUMIF('Raw Data'!$R:$R,$A5,'Raw Data'!$M:$M),4),"NA") -> NA
A6: ='Raw Data'!R3 -> One97 Communications Ltd (Paytm)_2022 | B6: =IFERROR(ROUND(SUMIF('Raw Data'!$R:$R,$A6,'Raw Data'!$I:$I)/SUMIF('Raw Data'!$R:$R,$A6,'Raw Data'!$F:$F),4),"NA") -> 0.0282 | C6: =IFERROR(ROUND(SUMIF('Raw Data'!$R:$R,$A6,'Raw Data'!$G:$G)/SUMIF('Raw Data'!$R:$R,$A6,'Raw Data'!$F:$F),4),"NA") -> 0 | D6: =IFERROR(ROUND(SUMIF('Raw Data'!$R:$R,$A6,'Raw Data'!$K:$K)/SUMIF('Raw Data'!$R:$R,$A6,'Raw Data'!$F:$F),4),"NA") -> -0.1332 | E6: =IFERROR(ROUND(LN(SUMIF('Raw Data'!$R:$R,$A6,'Raw Data'!$F:$F)),4),"NA") -> 9.7977 | F6: =IFERROR(ROUND(SUMIF('Raw Data'!$R:$R,$A6,'Raw Data'!$N:$N)/SUMIF('Raw Data'!$R:$R,$A6,'Raw Data'!$M:$M),4),"NA") -> 0.5
A7: ='Raw Data'!R4 -> One97 Communications Ltd (Paytm)_2023 | B7: =IFERROR(ROUND(SUMIF('Raw Data'!$R:$R,$A7,'Raw Data'!$I:$I)/SUMIF('Raw Data'!$R:$R,$A7,'Raw Data'!$F:$F),4),"NA") -> 0.0393 | C7: =IFERROR(ROUND(SUMIF('Raw Data'!$R:$R,$A7,'Raw Data'!$G:$G)/SUMIF('Raw Data'!$R:$R,$A7,'Raw Data'!$F:$F),4),"NA") -> 0.0001 | D7: =IFERROR(ROUND(SUMIF('Raw Data'!$R:$R,$A7,'Raw Data'!$K:$K)/SUMIF('Raw Data'!$R:$R,$A7,'Raw Data'!$F:$F),4),"NA") -> -0.0989 | E7: =IFERROR(ROUND(LN(SUMIF('Raw Data'!$R:$R,$A7,'Raw Data'!$F:$F)),4),"NA") -> 9.7962 | F7: =IFERROR(ROUND(SUMIF('Raw Data'!$R:$R,$A7,'Raw Data'!$N:$N)/SUMIF('Raw Data'!$R:$R,$A7,'Raw Data'!$M:$M),4),"NA") -> 0.5714
A8: ='Raw Data'!R5 -> One97 Communications Ltd (Paytm)_2024 | B8: =IFERROR(ROUND(SUMIF('Raw Data'!$R:$R,$A8,'Raw Data'!$I:$I)/SUMIF('Raw Data'!$R:$R,$A8,'Raw Data'!$F:$F),4),"NA") -> 0.0479 | C8: =IFERROR(ROUND(SUMIF('Raw Data'!$R:$R,$A8,'Raw Data'!$G:$G)/SUMIF('Raw Data'!$R:$R,$A8,'Raw Data'!$F:$F),4),"NA") -> 0 | D8: =IFERROR(ROUND(SUMIF('Raw Data'!$R:$R,$A8,'Raw Data'!$K:$K)/SUMIF('Raw Data'!$R:$R,$A8,'Raw Data'!$F:$F),4),"NA") -> -0.083 | E8: =IFERROR(ROUND(LN(SUMIF('Raw Data'!$R:$R,$A8,'Raw Data'!$F:$F)),4),"NA") -> 9.7491 | F8: =IFERROR(ROUND(SUMIF('Raw Data'!$R:$R,$A8,'Raw Data'!$N:$N)/SUMIF('Raw Data'!$R:$R,$A8,'Raw Data'!$M:$M),4),"NA") -> 0.5714
A9: ='Raw Data'!R6 -> PB Fintech Ltd (Policybazaar)_2021 | B9: =IFERROR(ROUND(SUMIF('Raw Data'!$R:$R,$A9,'Raw Data'!$I:$I)/SUMIF('Raw Data'!$R:$R,$A9,'Raw Data'!$F:$F),4),"NA") -> 0.0025 | C9: =IFERROR(ROUND(SUMIF('Raw Data'!$R:$R,$A9,'Raw Data'!$G:$G)/SUMIF('Raw Data'!$R:$R,$A9,'Raw Data'!$F:$F),4),"NA") -> 0 | D9: =IFERROR(ROUND(SUMIF('Raw Data'!$R:$R,$A9,'Raw Data'!$K:$K)/SUMIF('Raw Data'!$R:$R,$A9,'Raw Data'!$F:$F),4),"NA") -> -0.0645 | E9: =IFERROR(ROUND(LN(SUMIF('Raw Data'!$R:$R,$A9,'Raw Data'!$F:$F)),4),"NA") -> 7.7539 | F9: =IFERROR(ROUND(SUMIF('Raw Data'!$R:$R,$A9,'Raw Data'!$N:$N)/SUMIF('Raw Data'!$R:$R,$A9,'Raw Data'!$M:$M),4),"NA") -> NA
A10: ='Raw Data'!R7 -> PB Fintech Ltd (Policybazaar)_2022 | B10: =IFERROR(ROUND(SUMIF('Raw Data'!$R:$R,$A10,'Raw Data'!$I:$I)/SUMIF('Raw Data'!$R:$R,$A10,'Raw Data'!$F:$F),4),"NA") -> 0.0055 | C10: =IFERROR(ROUND(SUMIF('Raw Data'!$R:$R,$A10,'Raw Data'!$G:$G)/SUMIF('Raw Data'!$R:$R,$A10,'Raw Data'!$F:$F),4),"NA") -> 0 | D10: =IFERROR(ROUND(SUMIF('Raw Data'!$R:$R,$A10,'Raw Data'!$K:$K)/SUMIF('Raw Data'!$R:$R,$A10,'Raw Data'!$F:$F),4),"NA") -> -0.1408 | E10: =IFERROR(ROUND(LN(SUMIF('Raw Data'!$R:$R,$A10,'Raw Data'!$F:$F)),4),"NA") -> 8.6853 | F10: =IFERROR(ROUND(SUMIF('Raw Data'!$R:$R,$A10,'Raw Data'!$N:$N)/SUMIF('Raw Data'!$R:$R,$A10,'Raw Data'!$M:$M),4),"NA") -> 0.5556
A11: ='Raw Data'!R8 -> PB Fintech Ltd (Policybazaar)_2023 | B11: =IFERROR(ROUND(SUMIF('Raw Data'!$R:$R,$A11,'Raw Data'!$I:$I)/SUMIF('Raw Data'!$R:$R,$A11,'Raw Data'!$F:$F),4),"NA") -> 0.0105 | C11: =IFERROR(ROUND(SUMIF('Raw Data'!$R:$R,$A11,'Raw Data'!$G:$G)/SUMIF('Raw Data'!$R:$R,$A11,'Raw Data'!$F:$F),4),"NA") -> 0 | D11: =IFERROR(ROUND(SUMIF('Raw Data'!$R:$R,$A11,'Raw Data'!$K:$K)/SUMIF('Raw Data'!$R:$R,$A11,'Raw Data'!$F:$F),4),"NA") -> -0.078 | E11: =IFERROR(ROUND(LN(SUMIF('Raw Data'!$R:$R,$A11,'Raw Data'!$F:$F)),4),"NA") -> 8.741 | F11: =IFERROR(ROUND(SUMIF('Raw Data'!$R:$R,$A11,'Raw Data'!$N:$N)/SUMIF('Raw Data'!$R:$R,$A11,'Raw Data'!$M:$M),4),"NA") -> 0.5556
A12: ='Raw Data'!R9 -> PB Fintech Ltd (Policybazaar)_2024 | B12: =IFERROR(ROUND(SUMIF('Raw Data'!$R:$R,$A12,'Raw Data'!$I:$I)/SUMIF('Raw Data'!$R:$R,$A12,'Raw Data'!$F:$F),4),"NA") -> 0.0094 | C12: =IFERROR(ROUND(SUMIF('Raw Data'!$R:$R,$A12,'Raw Data'!$G:$G)/SUMIF('Raw Data'!$R:$R,$A12,'Raw Data'!$F:$F),4),"NA") -> 0 | D12: =IFERROR(ROUND(SUMIF('Raw Data'!$R:$R,$A12,'Raw Data'!$K:$K)/SUMIF('Raw Data'!$R:$R,$A12,'Raw Data'!$F:$F),4),"NA") -> 0.0096 | E12: =IFERROR(ROUND(LN(SUMIF('Raw Data'!$R:$R,$A12,'Raw Data'!$F:$F)),4),"NA") -> 8.8141 | F12: =IFERROR(ROUND(SUMIF('Raw Data'!$R:$R,$A12,'Raw Data'!$N:$N)/SUMIF('Raw Data'!$R:$R,$A12,'Raw Data'!$M:$M),4),"NA") -> 0.5556
A13: ='Raw Data'!R10 -> Computer Age Management Services Ltd (CAMS)_2021 | B13: =IFERROR(ROUND(SUMIF('Raw Data'!$R:$R,$A13,'Raw Data'!$I:$I)/SUMIF('Raw Data'!$R:$R,$A13,'Raw Data'!$F:$F),4),"NA") -> 0.0317 | C13: =IFERROR(ROUND(SUMIF('Raw Data'!$R:$R,$A13,'Raw Data'!$G:$G)/SUMIF('Raw Data'!$R:$R,$A13,'Raw Data'!$F:$F),4),"NA") -> 0 | D13: =IFERROR(ROUND(SUMIF('Raw Data'!$R:$R,$A13,'Raw Data'!$K:$K)/SUMIF('Raw Data'!$R:$R,$A13,'Raw Data'!$F:$F),4),"NA") -> 0.2438 | E13: =IFERROR(ROUND(LN(SUMIF('Raw Data'!$R:$R,$A13,'Raw Data'!$F:$F)),4),"NA") -> 6.7357 | F13: =IFERROR(ROUND(SUMIF('Raw Data'!$R:$R,$A13,'Raw Data'!$N:$N)/SUMIF('Raw Data'!$R:$R,$A13,'Raw Data'!$M:$M),4),"NA") -> 0.4286
A14: ='Raw Data'!R11 -> Computer Age Management Services Ltd (CAMS)_2022 | B14: =IFERROR(ROUND(SUMIF('Raw Data'!$R:$R,$A14,'Raw Data'!$I:$I)/SUMIF('Raw Data'!$R:$R,$A14,'Raw Data'!$F:$F),4),"NA") -> 0.065 | C14: =IFERROR(ROUND(SUMIF('Raw Data'!$R:$R,$A14,'Raw Data'!$G:$G)/SUMIF('Raw Data'!$R:$R,$A14,'Raw Data'!$F:$F),4),"NA") -> 0 | D14: =IFERROR(ROUND(SUMIF('Raw Data'!$R:$R,$A14,'Raw Data'!$K:$K)/SUMIF('Raw Data'!$R:$R,$A14,'Raw Data'!$F:$F),4),"NA") -> 0.2998 | E14: =IFERROR(ROUND(LN(SUMIF('Raw Data'!$R:$R,$A14,'Raw Data'!$F:$F)),4),"NA") -> 6.8639 | F14: =IFERROR(ROUND(SUMIF('Raw Data'!$R:$R,$A14,'Raw Data'!$N:$N)/SUMIF('Raw Data'!$R:$R,$A14,'Raw Data'!$M:$M),4),"NA") -> 0.4286
A15: ='Raw Data'!R12 -> Computer Age Management Services Ltd (CAMS)_2023 | B15: =IFERROR(ROUND(SUMIF('Raw Data'!$R:$R,$A15,'Raw Data'!$I:$I)/SUMIF('Raw Data'!$R:$R,$A15,'Raw Data'!$F:$F),4),"NA") -> 0.0406 | C15: =IFERROR(ROUND(SUMIF('Raw Data'!$R:$R,$A15,'Raw Data'!$G:$G)/SUMIF('Raw Data'!$R:$R,$A15,'Raw Data'!$F:$F),4),"NA") -> 0 | D15: =IFERROR(ROUND(SUMIF('Raw Data'!$R:$R,$A15,'Raw Data'!$K:$K)/SUMIF('Raw Data'!$R:$R,$A15,'Raw Data'!$F:$F),4),"NA") -> 0.2593 | E15: =IFERROR(ROUND(LN(SUMIF('Raw Data'!$R:$R,$A15,'Raw Data'!$F:$F)),4),"NA") -> 7.0008 | F15: =IFERROR(ROUND(SUMIF('Raw Data'!$R:$R,$A15,'Raw Data'!$N:$N)/SUMIF('Raw Data'!$R:$R,$A15,'Raw Data'!$M:$M),4),"NA") -> 0.4286
A16: ='Raw Data'!R13 -> Computer Age Management Services Ltd (CAMS)_2024 | B16: =IFERROR(ROUND(SUMIF('Raw Data'!$R:$R,$A16,'Raw Data'!$I:$I)/SUMIF('Raw Data'!$R:$R,$A16,'Raw Data'!$F:$F),4),"NA") -> 0.035 | C16: =IFERROR(ROUND(SUMIF('Raw Data'!$R:$R,$A16,'Raw Data'!$G:$G)/SUMIF('Raw Data'!$R:$R,$A16,'Raw Data'!$F:$F),4),"NA") -> 0 | D16: =IFERROR(ROUND(SUMIF('Raw Data'!$R:$R,$A16,'Raw Data'!$K:$K)/SUMIF('Raw Data'!$R:$R,$A16,'Raw Data'!$F:$F),4),"NA") -> 0.3198 | E16: =IFERROR(ROUND(LN(SUMIF('Raw Data'!$R:$R,$A16,'Raw Data'!$F:$F)),4),"NA") -> 7.0008 | F16: =IFERROR(ROUND(SUMIF('Raw Data'!$R:$R,$A16,'Raw Data'!$N:$N)/SUMIF('Raw Data'!$R:$R,$A16,'Raw Data'!$M:$M),4),"NA") -> 0.5
... A104: ='Raw Data'!R101 -> MAS Financial Services Ltd_2024 | B104: =IFERROR(ROUND(SUMIF('Raw Data'!$R:$R,$A104,'Raw Data'!$I:$I)/SUMIF('Raw Data'!$R:$R,$A104,'Raw Data'!$F:$F),4),"NA") -> 0.0007 | C104: =IFERROR(ROUND(SUMIF('Raw Data'!$R:$R,$A104,'Raw Data'!$G:$G)/SUMIF('Raw Data'!$R:$R,$A104,'Raw Data'!$F:$F),4),"NA") -> 0.7272 | D104: =IFERROR(ROUND(SUMIF('Raw Data'!$R:$R,$A104,'Raw Data'!$K:$K)/SUMIF('Raw Data'!$R:$R,$A104,'Raw Data'!$F:$F),4),"NA") -> 0.024 | E104: =IFERROR(ROUND(LN(SUMIF('Raw Data'!$R:$R,$A104,'Raw Data'!$F:$F)),4),"NA") -> 9.2667 | F104: =IFERROR(ROUND(SUMIF('Raw Data'!$R:$R,$A104,'Raw Data'!$N:$N)/SUMIF('Raw Data'!$R:$R,$A104,'Raw Data'!$M:$M),4),"NA") -> 0.6667
A107: Variable Definitions & Formulas
A108: Variable | B108: Formula | C108: Raw Data Column(s) Used
A109: FirmYear | B109: Firm name & fiscal year, e.g. "ABC Fintech_2022" | C109: Raw Data!A (Firm) + Raw Data!E (Year) | E109: Unique panel identifier (Firm x Year).
A110: Investment | B110: Capital Expenditure / Total Assets | C110: Raw Data!I (CAPEX) / Raw Data!F (Assets) | E110: No separate "Capital Expenditure" column exists in Raw Data; the CAPEX column is used as the investment variable.
A111: Leverage | B111: Total Debt / Total Assets | C111: Raw Data!G (Debt) / Raw Data!F (Assets) | E111: Where Debt = "Nil" in Raw Data, it is treated as 0 (zero formal debt), not missing.
A112: ROA | B112: Net Income / Total Assets | C112: Raw Data!K (Net Income) / Raw Data!F (Assets) | E112: Expressed as a decimal (e.g. 0.0523 = 5.23%), consistent across all rows.
A113: Firm Size | B113: LN(Total Assets) | C113: Raw Data!F (Assets) | E113: Natural log of Total Assets, per Excel's LN() function — not the raw Assets value.
A114: Board Independence | B114: Independent Directors / Total Directors | C114: Raw Data!N (Independent Directors) / Raw Data!M (Board Size) | E114: Expressed as a decimal. Returns "NA" for 3 firm-years where board composition was undisclosed pre-listing (Paytm FY2021, Policybazaar FY2021, Fino Payments Bank FY2021).
A116: General notes: Data is deplayed in Percentage (%) IFERROR() wraps every calculation so a missing raw value or a division by zero returns "NA" instead of an error or a false zero. Formulas key off a FirmYear lookup column added to Raw Data (column R) so this sheet always reflects the current Raw Data contents.

Sheet Descriptive Statistics
A1: Sheet 3 — Descriptive Statistics
A2: Corporate Governance, Financing Choices and Visible Investment Signals in Indian FinTech Firms: Evidence from Public Data
A4: Overall Descriptive Statistics — FY 2020-21 to FY 2023-24 (all firm-year observations)
A5: Variable | B5: N | C5: Mean | D5: Median | E5: Minimum | F5: Maximum | G5: Standard Deviation
A6: Investment | B6: =COUNT('Calculated Variables'!$B$5:$B$104) -> 100 | C6: =AVERAGE('Calculated Variables'!$B$5:$B$104) -> 0.016646 | D6: =MEDIAN('Calculated Variables'!$B$5:$B$104) -> 0.0082 | E6: =MIN('Calculated Variables'!$B$5:$B$104) -> 0.0004 | F6: =MAX('Calculated Variables'!$B$5:$B$104) -> 0.1411 | G6: =_xlfn.STDEV.S('Calculated Variables'!$B$5:$B$104) -> 0.020660866
A7: Leverage | B7: =COUNT('Calculated Variables'!$C$5:$C$104) -> 100 | C7: =AVERAGE('Calculated Variables'!$C$5:$C$104) -> 0.213145 | D7: =MEDIAN('Calculated Variables'!$C$5:$C$104) -> 0.0709 | E7: =MIN('Calculated Variables'!$C$5:$C$104) -> 0 | F7: =MAX('Calculated Variables'!$C$5:$C$104) -> 0.7659 | G7: =_xlfn.STDEV.S('Calculated Variables'!$C$5:$C$104) -> 0.27622211
A8: ROA | B8: =COUNT('Calculated Variables'!$D$5:$D$104) -> 100 | C8: =AVERAGE('Calculated Variables'!$D$5:$D$104) -> 0.080279 | D8: =MEDIAN('Calculated Variables'!$D$5:$D$104) -> 0.05305 | E8: =MIN('Calculated Variables'!$D$5:$D$104) -> -0.1859 | F8: =MAX('Calculated Variables'!$D$5:$D$104) -> 0.4525 | G8: =_xlfn.STDEV.S('Calculated Variables'!$D$5:$D$104) -> 0.10743455
A9: Firm Size | B9: =COUNT('Calculated Variables'!$E$5:$E$104) -> 100 | C9: =AVERAGE('Calculated Variables'!$E$5:$E$104) -> 8.147771 | D9: =MEDIAN('Calculated Variables'!$E$5:$E$104) -> 8.1738 | E9: =MIN('Calculated Variables'!$E$5:$E$104) -> 4.0872 | F9: =MAX('Calculated Variables'!$E$5:$E$104) -> 10.9711 | G9: =_xlfn.STDEV.S('Calculated Variables'!$E$5:$E$104) -> 1.2745885
A10: Board Independence | B10: =COUNT('Calculated Variables'!$F$5:$F$104) -> 97 | C10: =AVERAGE('Calculated Variables'!$F$5:$F$104) -> 0.52957835 | D10: =MEDIAN('Calculated Variables'!$F$5:$F$104) -> 0.5556 | E10: =MIN('Calculated Variables'!$F$5:$F$104) -> 0 | F10: =MAX('Calculated Variables'!$F$5:$F$104) -> 0.7778 | G10: =_xlfn.STDEV.S('Calculated Variables'!$F$5:$F$104) -> 0.13599491
A13: Baseline-Year Descriptive Statistics — 2020-21 (FY2021)
A14: Variable | B14: N | C14: Mean | D14: Median | E14: Minimum | F14: Maximum | G14: Standard Deviation
A15: Investment | B15: =COUNT($B$30:$B$129) -> 25 | C15: =AVERAGE($B$30:$B$129) -> 0.015684 | D15: =MEDIAN($B$30:$B$129) -> 0.0077 | E15: =MIN($B$30:$B$129) -> 0.0004 | F15: =MAX($B$30:$B$129) -> 0.0683 | G15: =_xlfn.STDEV.S($B$30:$B$129) -> 0.017620317
A16: Leverage | B16: =COUNT($C$30:$C$129) -> 25 | C16: =AVERAGE($C$30:$C$129) -> 0.21546 | D16: =MEDIAN($C$30:$C$129) -> 0.0823 | E16: =MIN($C$30:$C$129) -> 0 | F16: =MAX($C$30:$C$129) -> 0.7197 | G16: =_xlfn.STDEV.S($C$30:$C$129) -> 0.26084941
A17: ROA | B17: =COUNT($D$30:$D$129) -> 25 | C17: =AVERAGE($D$30:$D$129) -> 0.067492 | D17: =MEDIAN($D$30:$D$129) -> 0.0364 | E17: =MIN($D$30:$D$129) -> -0.1859 | F17: =MAX($D$30:$D$129) -> 0.4108 | G17: =_xlfn.STDEV.S($D$30:$D$129) -> 0.11674565
A18: Firm Size | B18: =COUNT($E$30:$E$129) -> 25 | C18: =AVERAGE($E$30:$E$129) -> 7.751772 | D18: =MEDIAN($E$30:$E$129) -> 7.8608 | E18: =MIN($E$30:$E$129) -> 4.0872 | F18: =MAX($E$30:$E$129) -> 10.2041 | G18: =_xlfn.STDEV.S($E$30:$E$129) -> 1.3365226
A19: Board Independence | B19: =COUNT($F$30:$F$129) -> 22 | C19: =AVERAGE($F$30:$F$129) -> 0.49594091 | D19: =MEDIAN($F$30:$F$129) -> 0.5 | E19: =MIN($F$30:$F$129) -> 0 | F19: =MAX($F$30:$F$129) -> 0.75 | G19: =_xlfn.STDEV.S($F$30:$F$129) -> 0.15152244
A22: Notes: Descriptive statistics are calculated from firm-year observations in Sheet 2 (Calculated Variables). The overall statistics cover the 2020-21 to 2023-24 period. Financial year 2020-21 is treated as the baseline year for comparison. Investment, Leverage, ROA, and Board Independence are reported as percentages. Firm Size is measured as the natural logarithm of Total Assets. Standard deviation is calculated using the sample standard deviation (STDEV.S).
A28: Baseline-Year (2020-21 / FY2021) Firm-Year Data — feeds the baseline table above
A29: FirmYear | B29: Investment | C29: Leverage | D29: ROA | E29: Firm Size | F29: Board Independence
A30: =IF(RIGHT('Calculated Variables'!$A5,4)="2021",'Calculated Variables'!$A5,"") -> One97 Communications Ltd (Paytm)_2021 | B30: =IF(RIGHT('Calculated Variables'!$A5,4)="2021",'Calculated Variables'!$B5,"") -> 0.0211 | C30: =IF(RIGHT('Calculated Variables'!$A5,4)="2021",'Calculated Variables'!$C5,"") -> 0.0595 | D30: =IF(RIGHT('Calculated Variables'!$A5,4)="2021",'Calculated Variables'!$D5,"") -> -0.1859 | E30: =IF(RIGHT('Calculated Variables'!$A5,4)="2021",'Calculated Variables'!$E5,"") -> 9.1217 | F30: =IF(RIGHT('Calculated Variables'!$A5,4)="2021",'Calculated Variables'!$F5,"") -> NA
A31: =IF(RIGHT('Calculated Variables'!$A6,4)="2021",'Calculated Variables'!$A6,"") | B31: =IF(RIGHT('Calculated Variables'!$A6,4)="2021",'Calculated Variables'!$B6,"") | C31: =IF(RIGHT('Calculated Variables'!$A6,4)="2021",'Calculated Variables'!$C6,"") | D31: =IF(RIGHT('Calculated Variables'!$A6,4)="2021",'Calculated Variables'!$D6,"") | E31: =IF(RIGHT('Calculated Variables'!$A6,4)="2021",'Calculated Variables'!$E6,"") | F31: =IF(RIGHT('Calculated Variables'!$A6,4)="2021",'Calculated Variables'!$F6,"")
A32: =IF(RIGHT('Calculated Variables'!$A7,4)="2021",'Calculated Variables'!$A7,"") | B32: =IF(RIGHT('Calculated Variables'!$A7,4)="2021",'Calculated Variables'!$B7,"") | C32: =IF(RIGHT('Calculated Variables'!$A7,4)="2021",'Calculated Variables'!$C7,"") | D32: =IF(RIGHT('Calculated Variables'!$A7,4)="2021",'Calculated Variables'!$D7,"") | E32: =IF(RIGHT('Calculated Variables'!$A7,4)="2021",'Calculated Variables'!$E7,"") | F32: =IF(RIGHT('Calculated Variables'!$A7,4)="2021",'Calculated Variables'!$F7,"")
A33: =IF(RIGHT('Calculated Variables'!$A8,4)="2021",'Calculated Variables'!$A8,"") | B33: =IF(RIGHT('Calculated Variables'!$A8,4)="2021",'Calculated Variables'!$B8,"") | C33: =IF(RIGHT('Calculated Variables'!$A8,4)="2021",'Calculated Variables'!$C8,"") | D33: =IF(RIGHT('Calculated Variables'!$A8,4)="2021",'Calculated Variables'!$D8,"") | E33: =IF(RIGHT('Calculated Variables'!$A8,4)="2021",'Calculated Variables'!$E8,"") | F33: =IF(RIGHT('Calculated Variables'!$A8,4)="2021",'Calculated Variables'!$F8,"")
A34: =IF(RIGHT('Calculated Variables'!$A9,4)="2021",'Calculated Variables'!$A9,"") -> PB Fintech Ltd (Policybazaar)_2021 | B34: =IF(RIGHT('Calculated Variables'!$A9,4)="2021",'Calculated Variables'!$B9,"") -> 0.0025 | C34: =IF(RIGHT('Calculated Variables'!$A9,4)="2021",'Calculated Variables'!$C9,"") -> 0 | D34: =IF(RIGHT('Calculated Variables'!$A9,4)="2021",'Calculated Variables'!$D9,"") -> -0.0645 | E34: =IF(RIGHT('Calculated Variables'!$A9,4)="2021",'Calculated Variables'!$E9,"") -> 7.7539 | F34: =IF(RIGHT('Calculated Variables'!$A9,4)="2021",'Calculated Variables'!$F9,"") -> NA
A35: =IF(RIGHT('Calculated Variables'!$A10,4)="2021",'Calculated Variables'!$A10,"") | B35: =IF(RIGHT('Calculated Variables'!$A10,4)="2021",'Calculated Variables'!$B10,"") | C35: =IF(RIGHT('Calculated Variables'!$A10,4)="2021",'Calculated Variables'!$C10,"") | D35: =IF(RIGHT('Calculated Variables'!$A10,4)="2021",'Calculated Variables'!$D10,"") | E35: =IF(RIGHT('Calculated Variables'!$A10,4)="2021",'Calculated Variables'!$E10,"") | F35: =IF(RIGHT('Calculated Variables'!$A10,4)="2021",'Calculated Variables'!$F10,"")
A36: =IF(RIGHT('Calculated Variables'!$A11,4)="2021",'Calculated Variables'!$A11,"") | B36: =IF(RIGHT('Calculated Variables'!$A11,4)="2021",'Calculated Variables'!$B11,"") | C36: =IF(RIGHT('Calculated Variables'!$A11,4)="2021",'Calculated Variables'!$C11,"") | D36: =IF(RIGHT('Calculated Variables'!$A11,4)="2021",'Calculated Variables'!$D11,"") | E36: =IF(RIGHT('Calculated Variables'!$A11,4)="2021",'Calculated Variables'!$E11,"") | F36: =IF(RIGHT('Calculated Variables'!$A11,4)="2021",'Calculated Variables'!$F11,"")
A37: =IF(RIGHT('Calculated Variables'!$A12,4)="2021",'Calculated Variables'!$A12,"") | B37: =IF(RIGHT('Calculated Variables'!$A12,4)="2021",'Calculated Variables'!$B12,"") | C37: =IF(RIGHT('Calculated Variables'!$A12,4)="2021",'Calculated Variables'!$C12,"") | D37: =IF(RIGHT('Calculated Variables'!$A12,4)="2021",'Calculated Variables'!$D12,"") | E37: =IF(RIGHT('Calculated Variables'!$A12,4)="2021",'Calculated Variables'!$E12,"") | F37: =IF(RIGHT('Calculated Variables'!$A12,4)="2021",'Calculated Variables'!$F12,"")
A38: =IF(RIGHT('Calculated Variables'!$A13,4)="2021",'Calculated Variables'!$A13,"") -> Computer Age Management Services Ltd (CAMS)_2021 | B38: =IF(RIGHT('Calculated Variables'!$A13,4)="2021",'Calculated Variables'!$B13,"") -> 0.0317 | C38: =IF(RIGHT('Calculated Variables'!$A13,4)="2021",'Calculated Variables'!$C13,"") -> 0 | D38: =IF(RIGHT('Calculated Variables'!$A13,4)="2021",'Calculated Variables'!$D13,"") -> 0.2438 | E38: =IF(RIGHT('Calculated Variables'!$A13,4)="2021",'Calculated Variables'!$E13,"") -> 6.7357 | F38: =IF(RIGHT('Calculated Variables'!$A13,4)="2021",'Calculated Variables'!$F13,"") -> 0.4286
A39: =IF(RIGHT('Calculated Variables'!$A14,4)="2021",'Calculated Variables'!$A14,"") | B39: =IF(RIGHT('Calculated Variables'!$A14,4)="2021",'Calculated Variables'!$B14,"") | C39: =IF(RIGHT('Calculated Variables'!$A14,4)="2021",'Calculated Variables'!$C14,"") | D39: =IF(RIGHT('Calculated Variables'!$A14,4)="2021",'Calculated Variables'!$D14,"") | E39: =IF(RIGHT('Calculated Variables'!$A14,4)="2021",'Calculated Variables'!$E14,"") | F39: =IF(RIGHT('Calculated Variables'!$A14,4)="2021",'Calculated Variables'!$F14,"")
A40: =IF(RIGHT('Calculated Variables'!$A15,4)="2021",'Calculated Variables'!$A15,"") | B40: =IF(RIGHT('Calculated Variables'!$A15,4)="2021",'Calculated Variables'!$B15,"") | C40: =IF(RIGHT('Calculated Variables'!$A15,4)="2021",'Calculated Variables'!$C15,"") | D40: =IF(RIGHT('Calculated Variables'!$A15,4)="2021",'Calculated Variables'!$D15,"") | E40: =IF(RIGHT('Calculated Variables'!$A15,4)="2021",'Calculated Variables'!$E15,"") | F40: =IF(RIGHT('Calculated Variables'!$A15,4)="2021",'Calculated Variables'!$F15,"")
A41: =IF(RIGHT('Calculated Variables'!$A16,4)="2021",'Calculated Variables'!$A16,"") | B41: =IF(RIGHT('Calculated Variables'!$A16,4)="2021",'Calculated Variables'!$B16,"") | C41: =IF(RIGHT('Calculated Variables'!$A16,4)="2021",'Calculated Variables'!$C16,"") | D41: =IF(RIGHT('Calculated Variables'!$A16,4)="2021",'Calculated Variables'!$D16,"") | E41: =IF(RIGHT('Calculated Variables'!$A16,4)="2021",'Calculated Variables'!$E16,"") | F41: =IF(RIGHT('Calculated Variables'!$A16,4)="2021",'Calculated Variables'!$F16,"")
... A129: =IF(RIGHT('Calculated Variables'!$A104,4)="2021",'Calculated Variables'!$A104,"") | B129: =IF(RIGHT('Calculated Variables'!$A104,4)="2021",'Calculated Variables'!$B104,"") | C129: =IF(RIGHT('Calculated Variables'!$A104,4)="2021",'Calculated Variables'!$C104,"") | D129: =IF(RIGHT('Calculated Variables'!$A104,4)="2021",'Calculated Variables'!$D104,"") | E129: =IF(RIGHT('Calculated Variables'!$A104,4)="2021",'Calculated Variables'!$E104,"") | F129: =IF(RIGHT('Calculated Variables'!$A104,4)="2021",'Calculated Variables'!$F104,"")

Sheet Correlation Matrix
A1: Sheet 4 — Correlation Matrix
A2: Corporate Governance, Financing Choices and Visible Investment Signals in Indian FinTech Firms: Evidence from Public Data
A4: Pairwise Pearson Correlation Matrix — Calculated Variables (Sheet 2)
B5: Investment | C5: Leverage | D5: ROA | E5: Firm Size | F5: Board Independence
A6: Investment | B6: =CORREL('Calculated Variables'!$B$5:$B$104,'Calculated Variables'!$B$5:$B$104) -> 1 | C6: =CORREL('Calculated Variables'!$B$5:$B$104,'Calculated Variables'!$C$5:$C$104) -> -0.37997417 | D6: =CORREL('Calculated Variables'!$B$5:$B$104,'Calculated Variables'!$D$5:$D$104) -> 0.20894462 | E6: =CORREL('Calculated Variables'!$B$5:$B$104,'Calculated Variables'!$E$5:$E$104) -> -0.27741673 | F6: =CORREL('Calculated Variables'!$B$5:$B$104,'Calculated Variables'!$F$5:$F$104) -> 0.078341664
A7: Leverage | B7: =C6 -> -0.37997417 | C7: =CORREL('Calculated Variables'!$C$5:$C$104,'Calculated Variables'!$C$5:$C$104) -> 1 | D7: =CORREL('Calculated Variables'!$C$5:$C$104,'Calculated Variables'!$D$5:$D$104) -> -0.12960328 | E7: =CORREL('Calculated Variables'!$C$5:$C$104,'Calculated Variables'!$E$5:$E$104) -> 0.30628383 | F7: =CORREL('Calculated Variables'!$C$5:$C$104,'Calculated Variables'!$F$5:$F$104) -> -0.1699826
A8: ROA | B8: =D6 -> 0.20894462 | C8: =D7 -> -0.12960328 | D8: =CORREL('Calculated Variables'!$D$5:$D$104,'Calculated Variables'!$D$5:$D$104) -> 1 | E8: =CORREL('Calculated Variables'!$D$5:$D$104,'Calculated Variables'!$E$5:$E$104) -> -0.53369413 | F8: =CORREL('Calculated Variables'!$D$5:$D$104,'Calculated Variables'!$F$5:$F$104) -> -0.40813993
A9: Firm Size | B9: =E6 -> -0.27741673 | C9: =E7 -> 0.30628383 | D9: =E8 -> -0.53369413 | E9: =CORREL('Calculated Variables'!$E$5:$E$104,'Calculated Variables'!$E$5:$E$104) -> 1 | F9: =CORREL('Calculated Variables'!$E$5:$E$104,'Calculated Variables'!$F$5:$F$104) -> 0.40003468
A10: Board Independence | B10: =F6 -> 0.078341664 | C10: =F7 -> -0.1699826 | D10: =F8 -> -0.40813993 | E10: =F9 -> 0.40003468 | F10: =CORREL('Calculated Variables'!$F$5:$F$104,'Calculated Variables'!$F$5:$F$104) -> 1
A12: Notes:
A13: Correlation coefficients are calculated using the firm-year observations in Sheet 2 (Calculated Variables). The matrix reports pairwise Pearson correlation coefficients among Investment, Leverage, ROA, Firm Size, and Board Independence. Correlation indicates the direction and strength of linear association and does not by itself establish causality.
